Workbook
Name 医療型障害児入所施設: 選択肢!$B$32:$K$32
Name 一般相談支援事業: 選択肢!$B$22:$K$22
Name 機能訓練: 選択肢!$B$16:$J$16
Name 居宅介護: 選択肢!$B$2:$K$2
Name 居宅介護・重度訪問介護・同行援護・行動援護: 選択肢!$B$2:$J$2
Name 居宅訪問型児童発達支援: 選択肢!$B$30:$K$30
Name 共同生活援助: 選択肢!$B$12:$K$12
Name 共同生活援助・介護サービス包括型: 選択肢!$B$12:$K$12
Name 共同生活援助・外部サービス利用型: 選択肢!$B$13:$K$13
Name 共同生活援助・日中サービス支援型: 選択肢!$B$14:$K$14
Name 行動援護: 選択肢!$B$5:$K$5
Name 児童発達支援・児童発達支援センターであるもの: 選択肢!$B$28:$L$28
Name 児童発達支援・主として重症心身障害児を対象とする場合: 選択肢!$B$27:$K$27
Name 児童発達支援・放課後等デイサービス: 選択肢!$B$26:$K$26
Name 自立生活援助: 選択肢!$B$24:$K$24
Name 就労移行支援: 選択肢!$B$19:$K$19
Name 就労継続支援Ａ型: 選択肢!$B$21:$K$21
Name 就労継続支援Ａ型・B型: 選択肢!$B$21:$K$21
Name 就労継続支援Ｂ型: 選択肢!$B$21:$K$21
Name 就労選択支援: 選択肢!$B$18:$K$18
Name 就労定着支援: 選択肢!$B$23:$K$23
Name 重度障害者等包括支援: 選択肢!$B$11:$K$11
Name 重度訪問介護: 選択肢!$B$3:$K$3
Name 障害者支援施設: 選択肢!$B$15:$L$15
Name 生活介護: 選択肢!$B$7:$K$7
Name 生活訓練: 選択肢!$B$17:$K$17
Name 短期入所・空床利用型: 選択肢!$B$9:$K$9
Name 短期入所・単独型: 選択肢!$B$10:$K$10
Name 短期入所・併設型: 選択肢!$B$8:$K$8
Name 同行援護: 選択肢!$B$4:$K$4
Name 特定相談支援・障害児相談支援: 選択肢!$B$25:$K$25
Name 認定指定就労移行支援: 選択肢!$B$20:$K$20
Name 福祉型障害児入所施設: 選択肢!$B$31:$K$31
Name 保育所等訪問支援: 選択肢!$B$29:$K$29
Name 療養介護: 選択肢!$B$6:$K$6

Sheet 勤務形態一覧表（児童発達支援・主として重症心身障害児）
A1: 従業者の勤務の体制及び勤務形態一覧表 | AI1: サービス種別 | AK1: 児童発達支援・主として重症心身障害児を対象とする場合
M2: 2024 | Q2: 年 | S2: 5 | U2: 月 | AI2: 事業所名
AI3: (1)記載する期間
AI4: (2)予定/実績の別
AI5: (2)-2 定員
AG6: (3)事業所における常勤の従業者が勤務すべき時間数 | AK6: 時間/週 | AM6: 時間/月
A8: No. | B8: (4)職種 | C8: (5)勤務形態 | D8: (6)資格 | E8: (7)氏名 | F8: (8) | AK8: (9)勤務時間数合計 | AL8: (10)週平均の勤務時間数 | AM8: (11)兼務状況 （兼務先／兼務する職務の内容）等
F9: 第１週 | M9: 第２週 | T9: 第３週 | AA9: 第４週 | AH9: 第５週
B10: ※選択肢にない職種については直接入力してください | F10: =DATE($M$2,$S$2,1) | G10: =DATE($M$2,$S$2,2) | H10: =DATE($M$2,$S$2,3) | I10: =DATE($M$2,$S$2,4) | J10: =DATE($M$2,$S$2,5) | K10: =DATE($M$2,$S$2,6) | L10: =DATE($M$2,$S$2,7) | M10: =DATE($M$2,$S$2,8) | N10: =DATE($M$2,$S$2,9) | O10: =DATE($M$2,$S$2,10) | P10: =DATE($M$2,$S$2,11) | Q10: =DATE($M$2,$S$2,12) | R10: =DATE($M$2,$S$2,13) | S10: =DATE($M$2,$S$2,14) | T10: =DATE($M$2,$S$2,15) | U10: =DATE($M$2,$S$2,16) | V10: =DATE($M$2,$S$2,17) | W10: =DATE($M$2,$S$2,18) | X10: =DATE($M$2,$S$2,19) | Y10: =DATE($M$2,$S$2,20) | Z10: =DATE($M$2,$S$2,21) | AA10: =DATE($M$2,$S$2,22) | AB10: =DATE($M$2,$S$2,23) | AC10: =DATE($M$2,$S$2,24) | AD10: =DATE($M$2,$S$2,25) | AE10: =DATE($M$2,$S$2,26) | AF10: =DATE($M$2,$S$2,27) | AG10: =DATE($M$2,$S$2,28) | AH10: =IF(DAY(EOMONTH(F10,0))<29,"",DATE($M$2,$S$2,29)) | AI10: =IF(DAY(EOMONTH(F10,0))<30,"",DATE($M$2,$S$2,30)) | AJ10: =IF(DAY(EOMONTH(F10,0))<31,"",DATE($M$2,$S$2,31))
F11: =DATE($M$2,$S$2,1) | G11: =DATE($M$2,$S$2,2) | H11: =DATE($M$2,$S$2,3) | I11: =DATE($M$2,$S$2,4) | J11: =DATE($M$2,$S$2,5) | K11: =DATE($M$2,$S$2,6) | L11: =DATE($M$2,$S$2,7) | M11: =DATE($M$2,$S$2,8) | N11: =DATE($M$2,$S$2,9) | O11: =DATE($M$2,$S$2,10) | P11: =DATE($M$2,$S$2,11) | Q11: =DATE($M$2,$S$2,12) | R11: =DATE($M$2,$S$2,13) | S11: =DATE($M$2,$S$2,14) | T11: =DATE($M$2,$S$2,15) | U11: =DATE($M$2,$S$2,16) | V11: =DATE($M$2,$S$2,17) | W11: =DATE($M$2,$S$2,18) | X11: =DATE($M$2,$S$2,19) | Y11: =DATE($M$2,$S$2,20) | Z11: =DATE($M$2,$S$2,21) | AA11: =DATE($M$2,$S$2,22) | AB11: =DATE($M$2,$S$2,23) | AC11: =DATE($M$2,$S$2,24) | AD11: =DATE($M$2,$S$2,25) | AE11: =DATE($M$2,$S$2,26) | AF11: =DATE($M$2,$S$2,27) | AG11: =DATE($M$2,$S$2,28) | AH11: =IF(DAY(EOMONTH(F11,0))<29,"",DATE($M$2,$S$2,29)) | AI11: =IF(DAY(EOMONTH(F11,0))<30,"",DATE($M$2,$S$2,30)) | AJ11: =IF(DAY(EOMONTH(F11,0))<31,"",DATE($M$2,$S$2,31))
A12: 1 | AK12: =+SUM(F12:AJ12) | AL12: =IF($AK$3="４週",AK12/4,AK12/(DAY(EOMONTH($F$10,0))/7)) | AO12: =IF(B12="","",IF(ISERROR(MATCH(B12,$C$37:$AM$37,0)),"その他職員",B12))
A13: 2 | AK13: =+SUM(F13:AJ13) | AL13: =IF($AK$3="４週",AK13/4,AK13/(DAY(EOMONTH($F$10,0))/7)) | AO13: =IF(B13="","",IF(ISERROR(MATCH(B13,$C$37:$AM$37,0)),"その他職員",B13))
A14: 3 | AK14: =+SUM(F14:AJ14) | AL14: =IF($AK$3="４週",AK14/4,AK14/(DAY(EOMONTH($F$10,0))/7)) | AO14: =IF(B14="","",IF(ISERROR(MATCH(B14,$C$37:$AM$37,0)),"その他職員",B14))
A15: 4 | AK15: =+SUM(F15:AJ15) | AL15: =IF($AK$3="４週",AK15/4,AK15/(DAY(EOMONTH($F$10,0))/7)) | AO15: =IF(B15="","",IF(ISERROR(MATCH(B15,$C$37:$AM$37,0)),"その他職員",B15))
A16: 5 | AK16: =+SUM(F16:AJ16) | AL16: =IF($AK$3="４週",AK16/4,AK16/(DAY(EOMONTH($F$10,0))/7)) | AO16: =IF(B16="","",IF(ISERROR(MATCH(B16,$C$37:$AM$37,0)),"その他職員",B16))
A17: 6 | AK17: =+SUM(F17:AJ17) | AL17: =IF($AK$3="４週",AK17/4,AK17/(DAY(EOMONTH($F$10,0))/7)) | AO17: =IF(B17="","",IF(ISERROR(MATCH(B17,$C$37:$AM$37,0)),"その他職員",B17))
A18: 7 | AK18: =+SUM(F18:AJ18) | AL18: =IF($AK$3="４週",AK18/4,AK18/(DAY(EOMONTH($F$10,0))/7)) | AO18: =IF(B18="","",IF(ISERROR(MATCH(B18,$C$37:$AM$37,0)),"その他職員",B18))
A19: 8 | AK19: =+SUM(F19:AJ19) | AL19: =IF($AK$3="４週",AK19/4,AK19/(DAY(EOMONTH($F$10,0))/7)) | AO19: =IF(B19="","",IF(ISERROR(MATCH(B19,$C$37:$AM$37,0)),"その他職員",B19))
A20: 9 | AK20: =+SUM(F20:AJ20) | AL20: =IF($AK$3="４週",AK20/4,AK20/(DAY(EOMONTH($F$10,0))/7)) | AO20: =IF(B20="","",IF(ISERROR(MATCH(B20,$C$37:$AM$37,0)),"その他職員",B20))
A21: 10 | AK21: =+SUM(F21:AJ21) | AL21: =IF($AK$3="４週",AK21/4,AK21/(DAY(EOMONTH($F$10,0))/7)) | AO21: =IF(B21="","",IF(ISERROR(MATCH(B21,$C$37:$AM$37,0)),"その他職員",B21))
A22: 11 | AK22: =+SUM(F22:AJ22) | AL22: =IF($AK$3="４週",AK22/4,AK22/(DAY(EOMONTH($F$10,0))/7)) | AO22: =IF(B22="","",IF(ISERROR(MATCH(B22,$C$37:$AM$37,0)),"その他職員",B22))
A23: 12 | AK23: =+SUM(F23:AJ23) | AL23: =IF($AK$3="４週",AK23/4,AK23/(DAY(EOMONTH($F$10,0))/7)) | AO23: =IF(B23="","",IF(ISERROR(MATCH(B23,$C$37:$AM$37,0)),"その他職員",B23))
... A31: 20 | AK31: =+SUM(F31:AJ31) | AL31: =IF($AK$3="４週",AK31/4,AK31/(DAY(EOMONTH($F$10,0))/7)) | AO31: =IF(B31="","",IF(ISERROR(MATCH(B31,$C$37:$AM$37,0)),"その他職員",B31))
A32: 合計 | F32: =+SUM(F12:F31) | G32: =+SUM(G12:G31) | H32: =+SUM(H12:H31) | I32: =+SUM(I12:I31) | J32: =+SUM(J12:J31) | K32: =+SUM(K12:K31) | L32: =+SUM(L12:L31) | M32: =+SUM(M12:M31) | ... AJ32: =+SUM(AJ12:AJ31) | AK32: =+SUM(F32:AJ32) | AL32: =IF($AK$3="４週",AK32/4,AK32/(DAY(EOMONTH($F$10,0))/7))
A33: サービス提供時間
A36: ＜人員基準に関する実人数集計＞ ※手入力いただいたものはすべて「その他職員」にまとめられます。
C37: =IF(VLOOKUP($AK$1,選択肢!$A$1:$J$32,C42,FALSE)=0,"-",VLOOKUP($AK$1,選択肢!$A$1:$J$32,C42,FALSE)) | E37: =IF(VLOOKUP($AK$1,選択肢!$A$1:$J$32,E42,FALSE)=0,"-",VLOOKUP($AK$1,選択肢!$A$1:$J$32,E42,FALSE)) | I37: =IF(VLOOKUP($AK$1,選択肢!$A$1:$J$32,I42,FALSE)=0,"-",VLOOKUP($AK$1,選択肢!$A$1:$J$32,I42,FALSE)) | O37: =IF(VLOOKUP($AK$1,選択肢!$A$1:$J$32,O42,FALSE)=0,"-",VLOOKUP($AK$1,選択肢!$A$1:$J$32,O42,FALSE)) | U37: =IF(VLOOKUP($AK$1,選択肢!$A$1:$J$32,U42,FALSE)=0,"-",VLOOKUP($AK$1,選択肢!$A$1:$J$32,U42,FALSE)) | AA37: =IF(VLOOKUP($AK$1,選択肢!$A$1:$J$32,AA42,FALSE)=0,"-",VLOOKUP($AK$1,選択肢!$A$1:$J$32,AA42,FALSE)) | AG37: =IF(VLOOKUP($AK$1,選択肢!$A$1:$J$32,AG42,FALSE)=0,"-",VLOOKUP($AK$1,選択肢!$A$1:$J$32,AG42,FALSE)) | AL37: =IF(VLOOKUP($AK$1,選択肢!$A$1:$J$32,AL42,FALSE)=0,"-",VLOOKUP($AK$1,選択肢!$A$1:$J$32,AL42,FALSE))
C38: 専従 | D38: 兼務 | E38: 専従 | F38: 兼務 | I38: 専従 | L38: 兼務 | O38: 専従 | R38: 兼務 | U38: 専従 | X38: 兼務 | AA38: 専従 | AD38: 兼務 | AG38: 専従 | AJ38: 兼務 | AL38: 専従 | AM38: 兼務
B39: 常勤 | C39: =COUNTIFS($AO$12:$AO$31,C$37,$C$12:$C$31,"A",$E$12:$E$31,"*") | D39: =COUNTIFS($AO$12:$AO$31,C$37,$C$12:$C$31,"B",$E$12:$E$31,"*") | E39: =COUNTIFS($AO$12:$AO$31,E$37,$C$12:$C$31,"A",$E$12:$E$31,"*") | F39: =COUNTIFS($AO$12:$AO$31,E$37,$C$12:$C$31,"B",$E$12:$E$31,"*") | I39: =COUNTIFS($AO$12:$AO$31,I$37,$C$12:$C$31,"A",$E$12:$E$31,"*") | L39: =COUNTIFS($AO$12:$AO$31,I$37,$C$12:$C$31,"B",$E$12:$E$31,"*") | O39: =COUNTIFS($AO$12:$AO$31,O$37,$C$12:$C$31,"A",$E$12:$E$31,"*") | R39: =COUNTIFS($AO$12:$AO$31,O$37,$C$12:$C$31,"B",$E$12:$E$31,"*") | U39: =COUNTIFS($AO$12:$AO$31,U$37,$C$12:$C$31,"A",$E$12:$E$31,"*") | X39: =COUNTIFS($AO$12:$AO$31,U$37,$C$12:$C$31,"B",$E$12:$E$31,"*") | AA39: =COUNTIFS($AO$12:$AO$31,AA$37,$C$12:$C$31,"A",$E$12:$E$31,"*") | AD39: =COUNTIFS($AO$12:$AO$31,AA$37,$C$12:$C$31,"B",$E$12:$E$31,"*") | AG39: =COUNTIFS($AO$12:$AO$31,AG$37,$C$12:$C$31,"A",$E$12:$E$31,"*") | AJ39: =COUNTIFS($AO$12:$AO$31,AG$37,$C$12:$C$31,"B",$E$12:$E$31,"*") | AL39: =COUNTIFS($AO$12:$AO$31,AL$37,$C$12:$C$31,"A",$E$12:$E$31,"*") | AM39: =COUNTIFS($AO$12:$AO$31,AL$37,$C$12:$C$31,"B",$E$12:$E$31,"*")
B40: 非常勤 | C40: =COUNTIFS($AO$12:$AO$31,C$37,$C$12:$C$31,"C",$E$12:$E$31,"*") | D40: =COUNTIFS($AO$12:$AO$31,C$37,$C$12:$C$31,"D",$E$12:$E$31,"*") | E40: =COUNTIFS($AO$12:$AO$31,E$37,$C$12:$C$31,"C",$E$12:$E$31,"*") | F40: =COUNTIFS($AO$12:$AO$31,E$37,$C$12:$C$31,"D",$E$12:$E$31,"*") | I40: =COUNTIFS($AO$12:$AO$31,I$37,$C$12:$C$31,"C",$E$12:$E$31,"*") | L40: =COUNTIFS($AO$12:$AO$31,I$37,$C$12:$C$31,"D",$E$12:$E$31,"*") | O40: =COUNTIFS($AO$12:$AO$31,O$37,$C$12:$C$31,"C",$E$12:$E$31,"*") | R40: =COUNTIFS($AO$12:$AO$31,O$37,$C$12:$C$31,"D",$E$12:$E$31,"*") | U40: =COUNTIFS($AO$12:$AO$31,U$37,$C$12:$C$31,"C",$E$12:$E$31,"*") | X40: =COUNTIFS($AO$12:$AO$31,U$37,$C$12:$C$31,"D",$E$12:$E$31,"*") | AA40: =COUNTIFS($AO$12:$AO$31,AA$37,$C$12:$C$31,"C",$E$12:$E$31,"*") | AD40: =COUNTIFS($AO$12:$AO$31,AA$37,$C$12:$C$31,"D",$E$12:$E$31,"*") | AG40: =COUNTIFS($AO$12:$AO$31,AG$37,$C$12:$C$31,"C",$E$12:$E$31,"*") | AJ40: =COUNTIFS($AO$12:$AO$31,AG$37,$C$12:$C$31,"D",$E$12:$E$31,"*") | AL40: =COUNTIFS($AO$12:$AO$31,AL$37,$C$12:$C$31,"C",$E$12:$E$31,"*") | AM40: =COUNTIFS($AO$12:$AO$31,AL$37,$C$12:$C$31,"D",$E$12:$E$31,"*")
B41: 常勤換算数 | C41: =IF($AK$3="４週",SUMIFS($AK$12:$AK$31,$AO$12:$AO$31,C37)/4/$AH$6,IF($AK$3="歴月",SUMIFS($AK$12:$AK$31,$AO$12:$AO$31,C37)/$AL$6,"記載する期間を選択してください")) | E41: =IF($AK$3="４週",SUMIFS($AK$12:$AK$31,$AO$12:$AO$31,E37)/4/$AH$6,IF($AK$3="歴月",SUMIFS($AK$12:$AK$31,$AO$12:$AO$31,E37)/$AL$6,"記載する期間を選択してください")) | I41: =IF($AK$3="４週",SUMIFS($AK$12:$AK$31,$AO$12:$AO$31,I37)/4/$AH$6,IF($AK$3="歴月",SUMIFS($AK$12:$AK$31,$AO$12:$AO$31,I37)/$AL$6,"記載する期間を選択してください")) | O41: =IF($AK$3="４週",SUMIFS($AK$12:$AK$31,$AO$12:$AO$31,O37)/4/$AH$6,IF($AK$3="歴月",SUMIFS($AK$12:$AK$31,$AO$12:$AO$31,O37)/$AL$6,"記載する期間を選択してください")) | U41: =IF($AK$3="４週",SUMIFS($AK$12:$AK$31,$AO$12:$AO$31,U37)/4/$AH$6,IF($AK$3="歴月",SUMIFS($AK$12:$AK$31,$AO$12:$AO$31,U37)/$AL$6,"記載する期間を選択してください")) | AA41: =IF($AK$3="４週",SUMIFS($AK$12:$AK$31,$AO$12:$AO$31,AA37)/4/$AH$6,IF($AK$3="歴月",SUMIFS($AK$12:$AK$31,$AO$12:$AO$31,AA37)/$AL$6,"記載する期間を選択してください")) | AG41: =IF($AK$3="４週",SUMIFS($AK$12:$AK$31,$AO$12:$AO$31,AG37)/4/$AH$6,IF($AK$3="歴月",SUMIFS($AK$12:$AK$31,$AO$12:$AO$31,AG37)/$AL$6,"記載する期間を選択してください")) | AL41: =IF($AK$3="４週",SUMIFS($AK$12:$AK$31,$AO$12:$AO$31,AL37)/4/$AH$6,IF($AK$3="歴月",SUMIFS($AK$12:$AK$31,$AO$12:$AO$31,AL37)/$AL$6,"記載する期間を選択してください"))
C42: 2 | E42: 3 | I42: 4 | O42: 5 | U42: 6 | AA42: 7 | AG42: 8 | AL42: 9
A43: ・最初に「年月欄」「サービス種別」「事業所名」を入力してください。 | R43: 6 | X43: 7 | AD43: 8 | AJ43: 9
A44: (1) 「４週」・「暦月」のいずれかを選択してください。
A45: (2) 「予定」・「実績」のいずれかを選択してください。
A46: (2) -2 定員数を入力してください。
A47: (3) 事業所における常勤の従業者が勤務すべき時間数を入力してください。
A48: (4) 従業者の職種を入力してください。
A49: 記入の順序は、職種ごとにまとめてください。
A50: (5) 従業者の勤務形態について、下記のうち該当する区分の記号を入力してください。
...

Sheet 選択肢
A1: ！申請するサービス類型を選択してください | B1: 職種① | C1: 職種② | D1: 職種③ | E1: 職種④ | F1: 職種⑤ | G1: 職種⑥ | H1: 職種⑦ | I1: 職種⑧ | J1: 職種⑨ | K1: 職種⑩
A2: 居宅介護 | B2: 管理者 | C2: サービス提供責任者 | D2: 従業者
A3: 重度訪問介護 | B3: 管理者 | C3: サービス提供責任者 | D3: 従業者
A4: 同行援護 | B4: 管理者 | C4: サービス提供責任者 | D4: 従業者
A5: 行動援護 | B5: 管理者 | C5: サービス提供責任者 | D5: 従業者
A6: 療養介護 | B6: 管理者 | C6: サービス管理責任者 | D6: 医師 | E6: 看護職員 | F6: 生活支援員
A7: 生活介護 | B7: 管理者 | C7: サービス管理責任者 | D7: 医師 | E7: 看護職員 | F7: 理学療法士 | G7: 作業療法士 | H7: 言語聴覚士 | I7: 生活支援員
A8: 短期入所・併設型 | B8: 管理者 | C8: 生活支援員
A9: 短期入所・空床利用型 | B9: 管理者 | C9: 生活支援員
A10: 短期入所・単独型 | B10: 管理者 | C10: 生活支援員
A11: 重度障害者等包括支援 | B11: 管理者 | C11: サービス提供責任者 | D11: 従業者
A12: 共同生活援助・介護サービス包括型 | B12: 管理者 | C12: サービス管理責任者 | D12: 世話人 | E12: 生活支援員
A13: 共同生活援助・外部サービス利用型 | B13: 管理者 | C13: サービス管理責任者 | D13: 世話人
A14: 共同生活援助・日中サービス支援型 | B14: 管理者 | C14: サービス管理責任者 | D14: 世話人 | E14: 生活支援員 | F14: 夜間支援従事者
A15: 障害者支援施設 | B15: 管理者 | C15: サービス管理責任者 | D15: 医師 | E15: 看護職員 | F15: 理学療法士 | G15: 作業療法士 | H15: 言語聴覚士 | I15: 就労支援員 | J15: 職業指導員 | K15: 生活支援員
A16: 機能訓練 | B16: 管理者 | C16: サービス管理責任者 | D16: 看護職員 | E16: 理学療法士 | F16: 作業療法士 | G16: 言語聴覚士 | H16: 生活支援員
A17: 生活訓練 | B17: 管理者 | C17: サービス管理責任者 | D17: 地域移行支援員 | E17: 生活支援員
A18: 就労選択支援 | B18: 管理者 | C18: 就労選択支援員
A19: 就労移行支援 | B19: 管理者 | C19: サービス管理責任者 | D19: 就労支援員 | E19: 職業指導員 | F19: 生活支援員
A20: 認定指定就労移行支援 | B20: 管理者 | C20: サービス管理責任者 | D20: 職業指導員 | E20: 生活支援員
A21: 就労継続支援Ａ型・Ｂ型 | B21: 管理者 | C21: サービス管理責任者 | D21: 職業指導員 | E21: 生活支援員
A22: 一般相談支援事業 | B22: 管理者 | C22: 従業者
A23: 就労定着支援 | B23: 管理者 | C23: サービス管理責任者 | D23: 就労定着支援員
A24: 自立生活援助 | B24: 管理者 | C24: サービス管理責任者 | D24: 地域生活支援員
A25: 特定相談支援・障害児相談支援 | B25: 管理者 | C25: 相談支援専門員 | D25: 相談支援員
A26: 児童発達支援・放課後等デイサービス | B26: 管理者 | C26: 児童発達支援管理責任者 | D26: 児童指導員 | E26: 保育士 | F26: 機能訓練担当職員 | G26: 看護職員 | H26: その他職員
A27: 児童発達支援・主として重症心身障害児を対象とする場合 | B27: 管理者 | C27: 児童発達支援管理責任者 | D27: 嘱託医 | E27: 看護職員 | F27: 児童指導員 | G27: 保育士 | H27: 機能訓練担当職員 | I27: その他職員
A28: 児童発達支援・児童発達支援センターであるもの | B28: 管理者 | C28: 児童発達支援管理責任者 | D28: 嘱託医 | E28: 児童指導員 | F28: 保育士 | G28: 栄養士 | H28: 調理員 | I28: 機能訓練担当職員 | J28: 看護職員 | K28: その他職員
A29: 保育所等訪問支援 | B29: 管理者 | C29: 児童発達支援管理責任者 | D29: 訪問支援員
A30: 居宅訪問型児童発達支援 | B30: 管理者 | C30: 児童発達支援管理責任者 | D30: 訪問支援員
A31: 福祉型障害児入所施設 | B31: 管理者 | C31: 児童発達支援管理責任者 | D31: 医師 | E31: 看護職員 | F31: 児童指導員 | G31: 保育士 | H31: 栄養士 | I31: 調理員 | J31: 心理担当職員
A32: 医療型障害児入所施設 | B32: 児童発達支援管理責任者 | C32: 医師 | D32: 看護職員 | E32: 児童指導員 | F32: 保育士 | G32: 心理担当職員 | H32: 理学療法士又は作業療法士 | I32: 職業指導員
